Workbook

Sheet Summary
B2: LCC Parks 4090000 - NA Review Programme - Status Summary
B3: Prepared 11-Jun-2026; updated 16-Jun-2026 | Spero Karkalemis | Ledger 26SLACT, O110-O115, P1-12 | No emails per standing directive; decisions are Spero's
B5: IN-SCOPE SPEND (87 ACCOUNTS) | E5: REVIEWED $ (SE2 COVERAGE BASIS) | H5: REVIEWED % OF SPEND | K5: ACCOUNTS WITH A REGISTER ROW
B6: =SUM('All Accounts'!D5:D91) -> 33891610 | E6: =SUM('All Accounts'!H5:H91) -> 497902.68 | H6: =SUM('All Accounts'!H5:H91)/SUM('All Accounts'!D5:D91) -> 0.014691031 | K6: =COUNTIF('All Accounts'!N5:N91,"<>")&" of 87" -> 21 of 87
B8: FULLY REVIEWED | E8: PARTIAL | H8: OPENED (NOT RECONCILED) | K8: NOT STARTED
B9: =COUNTIF('All Accounts'!G5:G91,"Fully reviewed") -> 13 | E9: =COUNTIF('All Accounts'!G5:G91,"Partial") -> 7 | H9: =COUNTIF('All Accounts'!G5:G91,"Opened") -> 1 | K9: =COUNTIF('All Accounts'!G5:G91,"Not started") -> 66
B11: Overall RAG across register accounts | GREEN clear, AMBER confirm, RED blocker, OPENED pre-reconciliation
B12: GREEN | E12: AMBER | H12: RED | K12: OPENED
B13: =COUNTIF('All Accounts'!N5:N91,"GREEN") -> 2 | E13: =COUNTIF('All Accounts'!N5:N91,"AMBER") -> 18 | H13: =COUNTIF('All Accounts'!N5:N91,"RED") -> 0 | K13: =COUNTIF('All Accounts'!N5:N91,"OPENED") -> 1
B15: Session headlines, 11-Jun-2026
B16: - Derived workbooks extended 11-Jun-2026 (fourth pass): the five handover workstreams (73211, 62121/62125, 7B532, 7B214, 73541) now carry rows here, in the Tracker and in the Running Transaction Listing (133 new listing lines).
B17: - 73211 worked and evidenced: intake C00228240 applied, 43 documents sighted, $157,051.42 of $236,378.27 (66.4%), all exact on the x1.1 test, 18 ABNs PASS; F5/F6 closed, F7 raised; GSTE-28 Telstra pattern recorded.
B18: - 73211 candidates held un-instructed (no recode dollar populated): F1 GJ079190 reversal, F2 ~$98,005 to 73212, F3 training/chair items, six new classification candidates.
B19: - 7B532 probable $1,232 IJ072723 duplicate held AMBER; 7B214 $7,488 oncharge backups outstanding; 62121/62125 destination-leg confirmation is the Garside residue; 73541 closes on the Trailbuilders backup.
B20: - Hard gates NONE. Register 22 rows, $538,947.73 ex-GST reviewed (recalc-verified); 16-Jun intake added NA7B213 Internal Medical (Immunisation) $4,861.70 and refreshed 73211 to $267,532.19 (+6 P12 lines, +$31,153.92, 17-Jun re-export); 73123 remains OPENED, not reconciled (gap $50,338.64).
B21: Basis note: SE2-coverage Reviewed-$ is anchored to the fixed 8-Jun SE2 and bridges to the register total $538,947.73 below. Differences: 73511 ($1,117.08, FBT batch pairs), 73512 ($8.42), post-SE2 P12 postings on 73211 ($31,454.92, incl the 17-Jun re-export's 6 new lines) and 7B214 ($3,888.00), the new 7B213 immunisation export over SE2 ($864.90), and the 62121/62125 revenue supplementary ($3,711.73) outside the 87-account expense scope. The tie-out below recomputes the bridge live.
B23: Register tie-out (live): SE2-coverage Reviewed-$ bridged to the Account Review Register
B24: Reviewed $ (SE2-coverage basis, 87 accounts) | E24: =SUM('All Accounts'!H5:H91) -> 497902.68
B25: + 73511 basis difference (register $5,384.57 net of FBT batch pairs) | E25: =5384.57-SUMIF('All Accounts'!B5:B91,"73511",'All Accounts'!H5:H91) -> 1117.08
B26: + 73512 basis difference (register $5,520.97 post-SE2) | E26: =5520.97-SUMIF('All Accounts'!B5:B91,"73512",'All Accounts'!H5:H91) -> 8.42
B27: + 73211 basis difference (register $267,532.19; +6 P12 lines, 17-Jun re-export) | E27: =267532.19-SUMIF('All Accounts'!B5:B91,"73211",'All Accounts'!H5:H91) -> 31454.92
B28: + 7B214 basis difference (register $7,570.50; P12 IJ074845) | E28: =7570.5-SUMIF('All Accounts'!B5:B91,"7B214",'All Accounts'!H5:H91) -> 3888
B29: + 7B213 basis difference (register $4,861.70; post-SE2 immunisation export) | E29: =4861.7-SUMIF('All Accounts'!B5:B91,"7B213",'All Accounts'!H5:H91) -> 864.9
B30: + 62121/62125 supplementary (revenue, outside the 87) | E30: ='All Accounts'!H94 -> 3711.73
B31: Register reviewed total (computed, = sum of the seven rows above) | E31: =SUM(E24:E30) -> 538947.73
B32: Register total per 00_Account_Review_Register.xlsx, 22 rows, 16-Jun-2026 | E32: 538947.73
B33: Tie-out | E33: =IF(ABS(E31-E32)<0.005,"TIES","CONFLICT - investigate before relying on this sheet") -> TIES

Sheet All Accounts
A1: LCC Parks 4090000 - Natural Account Review - Status of All Accounts
A2: All 87 in-scope natural accounts | Source SE2 8-Jun-2026, register and tracker as at 11-Jun-2026 | Batch CN-23167 | GL ex-GST
A4: Priority | B4: NA | C4: Account name | D4: Accum actual ex-GST | E4: Annual budget | F4: Materiality | G4: Review status | H4: Reviewed $ | I4: Untested $ | J4: L1 PK | K4: L2 NA | L4: L3 Evid | M4: L4 Tax | N4: Overall RAG | O4: Key finding (condensed) | P4: Remaining items | Q4: Evidence / artefacts | R4: Journal status | S4: Last reviewed
A5: P1 | B5: 72111 | C5: Minor Equipment & Supplies | D5: 67055.47 | E5: 97083.52 | F5: $10k-100k | G5: Partial | H5: 3433.91 | I5: 63621.56 | J5: GREEN | K5: RED | L5: GREEN | M5: GREEN | N5: AMBER | O5: AP-invoice pass: $2,260.36 of $3,433.91 miscoded (Tennyson signage 72222, Ultimate PPE 72113, STIHL GTA 40 72315, INITIATOR chem 72112). Doc46 journal pass recodes $22,028 off 72111 across 11 NAs. The two OVERLAP (Tennyson 27577 $335 in both) and cannot be summed. EVIDENCE SIGHTED 9-Jun (Ultimate/Woodmans/Tennyson set C00267478, all ABNs PASS): 3 Trees-PK (20241/PK000055) recodes now STAGED in NA72111_GENJNL_Recode.txt - trousers PIK2270125 $292.09 and pants PIK2267644 $402.59 to 72113 PPE (part... | P5: 1 Upload the 72111 streams (in the live journal). 2 Process GSTE-01 to 03 BAS adjustments ($69.50). 3 Spero scope call on the $63,621.56 untested remainder. Oasis/Pac Fire/Bunnings receipt GAPs closed 10-Jun-2026 (all four sighted, ABNs PASS, reconcile to the cent); Doc46 partial-recode remainders now content-known (PPE/decor candidates, un-instructed). | Q5: NA72111 note; _CarryForward Doc46/Doc45 source journals | R5: CN-23167 (PREPARED; NA72111_GENJNL_Recode.txt 14 lines, 4 sets) | S5: 9-Jun-2026
A6: P1 | B6: 73564 | C6: IT Equipment and Applications | D6: 43393.37 | E6: 60215.21 | F6: $10k-100k | G6: Fully reviewed | H6: 43393.37 | I6: 0 | J6: AMBER | K6: AMBER | L6: AMBER | M6: AMBER | N6: AMBER | O6: Full account $43,393.37 ex-GST, 36 lines (was partial $1,929.27). Findings: (a) 6 software/subscription lines $1,822.45 belong in 73566 IT Software Licence Fees (Esri, Anthropic, Body2 x2, 2 licence bundles); chart + P10 Canva/VisitUs precedent. (b) 9 of 20 recharge lines $4,416.27 off officer home PK incl confirmed Fry Depots->Trees miscode and likely AnneMarie/Caroline King mixup. (c) Esri INV000555 tax COMPLIANT (ABN PASS, GST exact, 1 of 7 seats). Body2 L18/L19 = correct monthly recognition ... | P6: 1 Finance accept 73564->73566 software recode $1,822.45 (held); confirm Body2 moved or left. 2 Confirm IT-recharge PK convention (home vs supported-team) for 9 lines. 3 Fry attribution CONFIRMED PK000001 (analyst); both positions map to PK000001. Release net-move 20241/PK000055->20151/PK000001 on SR-0315517 sighting. 4 Resolve King L08/L24 svc20191/PK000082. 5 Sight 7 no-attach SR backups: SR-0316577, SR-0315241, SR#204868, SR-0312575, SR#201404, SR-0315517, SR#200930 ($6,689.87). 6 Sight + tax-check 5 external invoices: 2412569490, INAU004378, GJ076194, GJ075813, TE005499. 6 Query L34 $3,761.60 quantum. 7 Advisory: P&A register for iPad/iPhone fleet. UPDATE 9-Jun: PK convention = officer home PK (Spero); 3 net-moves staged (Robertson/Dressman/Fry); sight SR219175/SR235810/SR-0315517 to clear their evidence limb; 6 King/Shearman lines still pending. | Q6: NA73564_Evidence/ (Esri INV000555 sighted; ledger extract); NA73564_GENJNL_Recode.txt (held; IT recharge schedule Feb-2026 sighted 10-Jun) | R6: CN-23167 (journal-ready, Spero; A 73564->73566 software, B 3 PK net-moves) | S6: 9-Jun-2026
A7: P1 | B7: 72312 | C7: Office & Library Equipment | D7: 2461.27 | E7: 0 | F7: $1k-10k | G7: Fully reviewed | H7: 2461.27 | J7: GREEN | K7: RED | L7: GREEN | M7: GREEN | N7: AMBER | O7: $2,461.27 of $2,461.27 (100%) miscoded out of 72312; IKEA EKET cabinets and Empire chair gas lifts + desk power + install all belong in 72313 Furniture & Fittings. IKEA line PK000493 CONFIRMED valid (Flying Gang, Park Services, svc 20392) per analyst sub-PK ledger; PK preserved as transacted, no PK move. Both ABNs checksum PASS. | P7: 1 Finance accept 72312 to 72313 recode in full-reversal format, then release CN-23167. 2 CAVEAT: pk_validator fails PK000493 (absent from installed maps which carry only PK000022 for svc 20392); add the Flying Gang sub-PK to lcc-coding-review so the recode validates. 3 Advisory: fix line 02 narration. | Q7: NA72312_Evidence/ (IKEA TE004431; Empire RL196475; ledger extract) | R7: CN-23167 (journal-ready, Spero) | S7: 8-Jun-2026
A8: P2 | B8: 73126 | C8: Landscapers & Gardeners | D8: 13198802 | E8: 15381295 | F8: >= $1M | G8: Not started | I8: 13198802 | P8: Not started. Obtain TechOne ledger export to open.
A9: P2 | B9: 73212 | C9: Major Contracts | D9: 7765424.1 | E9: 5318104.3 | F9: >= $1M | G9: Partial | H9: 54242.75 | I9: 7711181.4 | J9: AMBER | K9: RED | L9: AMBER | M9: AMBER | N9: AMBER | O9: A1 Strategy $15,100 (PO 708258) fails 73212 twice: four-element consultancy test met AND PO sits under the $20,000 floor; recode candidate to 73601 held (Tier 1 complete: 3 invoices + ABR x2 + ASIC, GST exact, hours recompute). Aust Care $630 invoice names PK000496, ledger charged PK000469 (PK recode candidate). GJ079210 -$66,183.82 one-sided Play Force move is the open dollar; ~$30,000 standing-order lines vendor-blind. | 11-Jun: GJ079210 backup SIGHTED - balanced 6-line PK move PK000035 to PK0... | P9: 1 Spero rulings: A1 $15,100 73212->73601 (73603 alt); Aust Care PK000469->PK000496 $630. 2 GJ079210 + GJ076924 backups CLOSED 11-Jun-2026 (sighted, balanced, direction verified). 3 Vendor invoices for s4090230 standing orders (~$30,000). 4 Contracts vs the $20k floor: LCC-09-2022, Aust Care SO, Play Force. 5 Trace IPWEA $343.20 part-payment. 6 Confirm Anita Moore home service (OrgRisk invoice now corroborates Acting Parks Manager). | Q9: NA73212_Evidence/ (8 files, hash-verified) | R9: n/a (candidates held, no recode staged) | S9: 10-Jun-2026
A10: P2 | B10: 73123 | C10: Maintenance Services | D10: 3900770.8 | E10: 8330733.3 | F10: >= $1M | G10: Opened | H10: 0 | I10: 3900770.8 | J10: n/a | K10: n/a | L10: n/a | M10: n/a | N10: OPENED | O10: OPENED ONLY, no limb rated. Export sums $3,951,109.43 vs SE2 (8-Jun) $3,900,770.79: gap $50,338.64 unresolved (suspected export row duplication - 365 exact-duplicate rows $20,201.46, accrual legs appearing in triplicate - and/or 8-to-11-Jun P12 timing). Per session rule no conclusions until reconciled, so Reviewed-$ stays $0. Profile: AP $3,971,119.30 over 3,339 rows; GL net -$23,019.35 (self-reversing EOM accruals + 2 Pool Shop recodes out); top services 20392 $1,304,200 and 20481 $1,273,366 (6... | P10: 1 Resolve the $50,338.64 export-vs-SE2 gap (re-pull or P12 diff) BEFORE any line work. 2 Read jointly with 73212 (GJ076924 redistribution touches both). 3 Plan line review by service: 20392 and 20481 first. | Q10: NA73123_Scope_Note.md; NA73123_Evidence/ (full + 2 section ledger extracts) | R10: n/a (not worked) | S10: 11-Jun-2026 (opened)
A11: P2 | B11: 73990 | C11: Expensed capital services | D11: 3051433.7 | E11: 4000000 | F11: >= $1M | G11: Not started | I11: 3051433.7 | P11: Not started. Obtain TechOne ledger export to open.
A12: P3 | B12: 7C111 | C12: Internal - Vehicle/Plant Hire | D12: 1844939.6 | E12: 2130960 | F12: >= $1M | G12: Not started | I12: 1844939.6 | P12: Not started. Obtain TechOne ledger export to open.
A13: P3 | B13: 7B115 | C13: Internal - Garbage Charges | D13: 871434.07 | E13: 29417.39 | F13: $100k-1M | G13: Not started | I13: 871434.07 | P13: Not started. Obtain TechOne ledger export to open.
A14: P3 | B14: 73121 | C14: Cleaning & Sanitary | D14: 668784.41 | E14: 1160178.8 | F14: $100k-1M | G14: Not started | I14: 668784.41 | P14: Not started. Obtain TechOne ledger export to open.
A15: P3 | B15: 7B112 | C15: Internal - Water Base Charge | D15: 363931.78 | E15: 346422.15 | F15: $100k-1M | G15: Not started | I15: 363931.78 | P15: Not started. Obtain TechOne ledger export to open.
A16: P3 | B16: 7B113 | C16: Internal - Water Usage Charge | D16: 339375.43 | E16: 276596.57 | F16: $100k-1M | G16: Not started | I16: 339375.43 | P16: Not started. Obtain TechOne ledger export to open.
A17: P3 | B17: 73124 | C17: Security | D17: 264132.36 | E17: 5579.2 | F17: $100k-1M | G17: Not started | I17: 264132.36 | P17: Not started. Obtain TechOne ledger export to open.
A18: P3 | B18: 73211 | C18: Minor Contracts (below $20,000) | D18: 236077.27 | E18: 894312.41 | F18: $100k-1M | G18: Fully reviewed | H18: 236077.27 | I18: 0 | J18: AMBER | K18: AMBER | L18: AMBER | M18: AMBER | N18: AMBER | O18: Reconciles to the 11-Jun SE2 to the cent: $236,378.27 register basis, 114 lines, 23 cost codes (this sheet carries the 8-Jun SE2 actual $236,077.27; the $301.00 difference is the P12 Lockwise line 2908883 posted 8-Jun-2026). Intake C00228240 applied 11-Jun: 43 documents sighted, $157,051.42 (66.4%) evidenced, every document exact on the x1.1 test, 18 ABN checksums PASS. Findings: F1 $5,635 GJ079190 duplicates GJ079210 onto PK000022 (Gihani 6-May-2026 instruction sighted: 510>PK000023, 511>PK000022); F2 ~$98,005 above-threshold candidates to 73212 (LCC31326 $25,848.08, Destination Trails $43,114, Chronicle $29,042.45); F3 training/chair items (PRINCE2 $2,440, PSIA $4,300, IPWEA $2,788, chair $370.05); F4 GJ078546 destinations unverified plus Provac $2,050 inbound query; F7 TE004838 cover slip vs posting mismatch; F5 and F6 CLOSED. Six new classification candidates (Firesight 73601, Chronicle 73566/survey, Tennyson 72222, SC10918 64411, Telstra telecoms, INCON materials). GSTE-28 Telstra cents-level pattern. | P18: 1 Spero rulings on F1 (reversal and re-post destination), the F2/F3 candidate sets and the six new candidates (single sweep). 2 Sight the remaining gap documents ($79,326.85 incl 2906937 $10,200, 2908705 $17,000, TBM series $15,604.11, Ausecology $14,840). 3 Run the ABR sightings queue (18 suppliers; INCON and IPWEA done). 4 No recode dollar populates without the ruling. | Q18: 02_NA73211_Minor_Contracts/ (Verification Record; 43 evidence PDFs + manifest with GAP rows; Related/) | R18: n/a (no recode staged; candidates held un-instructed) | S18: 11-Jun-2026
A19: P3 | B19: 7B114 | C19: Internal - Sewerage Charges | D19: 204911.46 | E19: 197323.14 | F19: $100k-1M | G19: Not started | I19: 204911.46 | P19: Not started. Obtain TechOne ledger export to open.
A20: P3 | B20: 7C112 | C20: Internal - Miscellaneous Plant Hire | D20: 163135.45 | E20: 0 | F20: $100k-1M | G20: Not started | I20: 163135.45 | P20: Not started. Obtain TechOne ledger export to open.
A21: P3 | B21: 73312 | C21: Electricity | D21: 157505.76 | E21: 174568.78 | F21: $100k-1M | G21: Not started | I21: 157505.76 | P21: Not started. Obtain TechOne ledger export to open.
A22: P3 | B22: 72231 | C22: Landscape Supplies | D22: 150347.57 | E22: 99731.71 | F22: $100k-1M | G22: Not started | I22: 150347.57 | P22: Not started. Obtain TechOne ledger export to open.
A23: P4 | B23: 73544 | C23: Training & Development | D23: 69232.16 | E23: 65134.88 | F23: $10k-100k | G23: Fully reviewed | H23: 69232.16 | I23: 0 | J23: AMBER | K23: AMBER | L23: AMBER | M23: AMBER | N23: AMBER | O23: Account reconciles. 21 references evidenced incl Whitehead $18,750, Fire Mgmt $10,500, Bendelta $8,966.28 (consultancy recode candidate to 73601), BAL $1,767 (73541 candidate; HLW dossier sighted, tax invoice outstanding), PSIA narration error. GST errors: Blue Dog $11.73 (GSTE-25), Barter $9.52 (GSTE-26), OIR $8.76 corrected (GSTE-27). 11-Jun: PK-split recode STAGED $2,131.46 (GJ079650 chargebacks $949.64 + ACCA split $1,181.82, 9 lines, nets $0.00, re-verified); Pryor/Hambly held; Preussner GJ... | P23: 1 Upload NA73544_GENJNL_Recode.txt (in the live journal). 2 Spero rulings: Bendelta->73601 $8,966.28; BAL 73541-vs-73544 $1,767; Warnholtz concurrence; Pryor PK000044-vs-PK000003 $214.00; Hambly $294.42 (not in map); Preussner destination query. 3 Sight: HLW tax invoice, OIR source receipt, 7 journal backups ~$11,100. 4 Confirm Moore/Moir/Funk services (EOM report). 5 BAS: GSTE-25/26 reversals. | 11-Jun: journal backups now 6 outstanding (~$10,600: IJ074222, GJ078710, GJ078895, GJ077155, GJ079267, GJ078296); OIR source receipt CLOSED. | Q23: NA73544_Evidence/ (36 files: session set hash-verified + back-charges set hashed this session) | R23: CN-23167 (journal-ready, Spero 11-Jun-2026; NA73544 PK-split stream in the live journal) | S23: 11-Jun-2026
A24: P4 | B24: 73422 | C24: Fire Levy | D24: 63803.78 | E24: 60788.01 | F24: $10k-100k | G24: Not started | I24: 63803.78 | P24: Not started. Obtain TechOne ledger export to open.
A25: P4 | B25: 73535 | C25: Tollway Charges | D25: 46010.25 | E25: 44775.05 | F25: $10k-100k | G25: Not started | I25: 46010.25 | P25: Not started. Obtain TechOne ledger export to open.
A26: P4 | B26: 73601 | C26: Management Consultancies | D26: 46003.66 | E26: 45000 | F26: $10k-100k | G26: Fully reviewed | H26: 46003.66 | I26: 0 | J26: GREEN | K26: GREEN | L26: GREEN | M26: GREEN | N26: GREEN | O26: Full account parsed, 9 lines $46,003.66, reconciles to SE2 exact. Single engagement: Organisational Risk Consulting Pty Ltd, Parks Branch WHS Gap Analysis (Consultancy Agreement, T&M, consultant Andrea Paynter, PO 711200/712924). 1 of 9 invoices sighted: INV-251010(2) $2,132.63 via GJ078546, GST $213.26 exact, $2,345.89 incl = GL x 1.1 exact; consultancy four-element test met on the face; 73601 correct. Invoice addressee corroborates Anita Moore as Acting Parks Manager (bears on her home-service... EVIDENCE CLOSED 16-Jun: 8 Org Risk Consulting invoices sighted ($43,871.03 exact), 9 of 9, all A | P26: 1 Obtain the 8 Org Risk invoices ($43,871.03). 2 Run ABR/ASIC dossier on ABN 27 651 588 662 when the set lands. 3 Check engagement period vs the 12-month contractor cap (runs 30-Jul-2025 onward on sighted docs). | Q26: NA73601_Evidence/ (INV-251010(2) + ledger extract); NA73601_Evidence_Manifest.csv (gap-listed) | R26: n/a (no recode expected; coding correct on sighted line) | S26: 11-Jun-2026
A27: P4 | B27: 7B111 | C27: Internal - Rates & Charges | D27: 34840.97 | E27: 3663.8 | F27: $10k-100k | G27: Not started | I27: 34840.97 | P27: Not started. Obtain TechOne ledger export to open.
A28: P4 | B28: 72315 | C28: Parks Assets | D28: 27971.77 | E28: 0 | F28: $10k-100k | G28: Not started | I28: 27971.77 | P28: Not started. Obtain TechOne ledger export to open.
A29: P4 | B29: 72112 | C29: Chemical, fertiliser & paints | D29: 27073.1 | E29: 2624.88 | F29: $10k-100k | G29: Not started | I29: 27073.1 | P29: Not started. Obtain TechOne ledger export to open.
A30: P4 | B30: 72114 | C30: Uniforms | D30: 26236.42 | E30: 49051.52 | F30: $10k-100k | G30: Partial | H30: 1059.76 | I30: 25176.66 | J30: AMBER | K30: GREEN | L30: AMBER | M30: N/A | N30: AMBER | O30: 3-Jun Reali PK split $1,059.76 confirmed subset (~4%). GJ SOURCE NOW SIGHTED (Document Reconstruction, doc 202603161072172000000001, ledger 26SLACT): a BALANCED multi-account recode batch (nets $0.00). Its 72114 block credits $10,650.27 from 1-20001-72114 narrated 'Institute of Public Works Engineering Au' (IPWEA) and DEBITS the same $10,650.27 across 16 service-level 72114 (Uniforms) PKs. CONCERN: if the $10,650.27 is a genuine IPWEA professional charge it should leave 72114 entirely (73542 Pro... | P30: 1 Confirm whether the reconstruction batch is POSTED or PROPOSED; if posted, the IPWEA $10,650.27 is already spread across Uniforms service PKs. 2 Obtain the underlying IPWEA invoice to confirm nature (membership vs conference vs training) and set destination (73542/73541/73544); it should not sit in 72114. 3 Work the now-provided Reali set at full scope. 4 Confirm net-movement vs full-reversal format. Same batch also shows other apparent miscodes outside scope (e.g. Empire Office Furniture $4,300 in 73544 Training). | 10-Jun: Reali Mar-2026 invoice sighted (GSTE-06 $0.01 note); officer split basis captured, not journalled | Q30: NA72114_Scope_Note.md; Document_Reconstruction (GJ source) sighted; C00223414 Reali set provided; 00_Uniform_Listing_72114.xlsx (full account, per-line) | R30: CN-23167 (journal-ready, Spero) | S30: 9-Jun-2026
A31: P4 | B31: 72113 | C31: Safety Equipment & Medical Supplies | D31: 25223.19 | E31: 44586.46 | F31: $10k-100k | G31: Not started | I31: 25223.19 | P31: Not started. Obtain TechOne ledger export to open.
A32: P4 | B32: 7B122 | C32: Internal - Tip Fees | D32: 23267.12 | E32: 10492.41 | F32: $10k-100k | G32: Not started | I32: 23267.12 | P32: Not started. Obtain TechOne ledger export to open.
A33: P4 | B33: 73122 | C33: Garbage Collection | D33: 21876.6 | E33: 1152061.7 | F33: $10k-100k | G33: Not started | I33: 21876.6 | P33: Not started. Obtain TechOne ledger export to open.
A34: P4 | B34: 73609 | C34: Other Consultancies | D34: 21730 | E34: 0 | F34: $10k-100k | G34: Not started | I34: 21730 | P34: Not started. Obtain TechOne ledger export to open.
A35: P4 | B35: 73128 | C35: Other services | D35: 17155.73 | E35: 5469.81 | F35: $10k-100k | G35: Partial | H35: 1854.7 | I35: 15301.03 | J35: GREEN | K35: RED | L35: GREEN | M35: GREEN | N35: AMBER | O35: $1,854.70 of $1,854.70 (100%) of the milk spend miscoded to 73128 last-resort services; goods purchase belongs in 73512 Entertainment & Hospitality Non-FBT (recode instructed by Spero 10-Jun-2026). All 50 unique invoices and the bond refund documents sighted; account reconciles to the ledger with no residual. 16 GST errors confirmed, $61.11 ITC over-claimed Jun-2025 to mid-Sep-2025 (corrected at source from INV-399504), recorded GSTE-07 to GSTE-22; bond refund net-nil GST timing note $272.73 rec... | P35: 1 Upload NA73128_GENJNL_Recode.txt (122 lines, 61 pairs, nets $0.00, direction verified). 2 Process the $61.11 BAS adjustment (GSTE-07 to GSTE-22); no GENJNL movement. 3 Package the 56 per-line evidence PDFs into NA73128_Evidence/ (sighted 10-Jun-2026, SHA-256 fingerprints held in NA73128_Workstream_Manifest_10-Jun-2026.csv; only the compressed second-intake binder is carried this bundle). | Q35: NA73128_Evidence/ (second-intake binder C00216123; ledger extract; ABR record); NA73128_Evidence_Manifest.csv (59 rows, no GAP) | R35: CN-23167 (journal-ready, Spero 10-Jun-2026) | S35: 10-Jun-2026
A36: P4 | B36: 73412 | C36: Refund of Operational Contributions | D36: 15477.09 | E36: 0 | F36: $10k-100k | G36: Not started | I36: 15477.09 | P36: Not started. Obtain TechOne ledger export to open.
A37: P4 | B37: 7B411 | C37: Internal - IT Equipment & Application | D37: 13130 | E37: 1640.95 | F37: $10k-100k | G37: Not started | I37: 13130 | P37: Not started. Obtain TechOne ledger export to open.
A38: P4 | B38: 7B211 | C38: Internal - Property-based Professional S | D38: 11000 | E38: 1934.81 | F38: $10k-100k | G38: Not started | I38: 11000 | P38: Not started. Obtain TechOne ledger export to open.
A39: P4 | B39: 7BZ11 | C39: Internal - Community Service Obligations | D39: 10929.72 | E39: 4088.78 | F39: $10k-100k | G39: Not started | I39: 10929.72 | P39: Not started. Obtain TechOne ledger export to open.
A40: P5 | B40: 7B123 | C40: Internal - Other fees & Charges | D40: 9542.69 | E40: 945.91 | F40: $1k-10k | G40: Not started | I40: 9542.69 | P40: Not started. Obtain TechOne ledger export to open.
A41: P5 | B41: 73563 | C41: Printing & Stationery | D41: 9495.37 | E41: 7322.24 | F41: $1k-10k | G41: Fully reviewed | H41: 9495.37 | I41: 0 | J41: GREEN | K41: RED | L41: GREEN | M41: GREEN | N41: AMBER | O41: $6,354.47 of $9,495.37 (66.9%) miscoded out of 73563 (WINC catch-all + Officeworks TE005250); recode journal-ready. Evidence re-verified 10-Jun-2026: all eleven WINC tax-invoice summaries sighted and reconciled per cost centre to the cent (GL ex-GST base equals invoice ex-GST every month); GST-free refreshment content (34 lines $1,195.79) correctly booked off invoice GST, no phantom ITC; stores lines 094908/096380 closed under the Marsden convention (envelope item 207144, code collision document... | P41: 1 Upload the 73563 recode (in the live journal). 2 50/50-batch data check on the 73512 movements (Reason B). 3 Sight the TE005154 backup ($136.80) - the last evidence item - or Spero waiver. | Q41: NA73563_Evidence/ (11 WINC invoices incl 9 newly sighted P1-P10, Officeworks 628185694, audit, recon, ledger) | R41: CN-23167 (journal-ready, Spero) | S41: 9-Jun-2026
...

Sheet Open Items
A1: CN-23167 Open Items Register - everything still open, by account
A2: Mirrors 00_Outstanding_Evidence_and_Actions.md as at 11-Jun-2026 (fourth pass) | Documents to sight, Spero decisions, internal work | Hard gates: NONE
A4: # | B4: Type | C4: Account | D4: Item | E4: Status / note
A5: 1 | B5: Document | C5: 73511 | D5: Warnholtz invoice 001 ($744.30, narrated Training) | E5: GAP; payee not in employee map
A6: 2 | B6: Document | C6: 73511 | D6: Receipts for the PCard/reimbursement net population | E6: GAP; per-line GST-free food check pending
A7: 3 | B7: Document | C7: 73511 | D7: Greenbank engagement residuals: the $700.00 room hire payment trace and the $200.00 bond return | E7: GAP; non-blocking on the INV-9747 line
A8: 4 | B8: Document | C8: 73533 | D8: ibis Melbourne (Accor) tax invoice for the $288.18 accommodation | E8: Advisory; GST waived by Spero, ITC exposure noted
A9: 5 | B9: Document | C9: 73140 | D9: Sample of CV Check AP invoices | E9: GAP; numbers unknown
A10: 6 | B10: Document | C10: 73140 | D10: FY26 73140 ledger extract, to apply the five held Kinatico invoices (P00075671, P00081314, P00082255, P00083290, P00086890; ABN 25 111 728 842, PO 801790) | E10: NARROWED 11-Jun-2026: invoices in hand in 07_Intake_Held_Kinatico/ (Kinatico is the CVCheck parent); held unapplied per the evidence rule, zero AP document hits in the 11-Jun exports
A11: 7 | B11: Document | C11: 73564 | D11: SR backups: SR219175 (Robertson), SR-0315517 (Fry) | E11: GAP; SR235810 (Dresman) CLOSED 10-Jun; lines journal-ready on directive
A12: 8 | B12: Document | C12: 73564 | D12: Other no-attachment SR backups and five external invoices (2412569490, INAU004378, GJ076194, GJ075813, TE005499) | E12: GAP; six off-home lines still open
A13: 9 | B13: Document | C13: 72111 / 72114 | D13: Full ledger remainders | E13: GAP; large untested balances
A14: 10 | B14: Document | C14: 73128 | D14: Per-line evidence split set (56 PDFs; all 50 TCB invoices + bond support) | E14: Packaging GAP only; all sighted 10-Jun-2026, SHA-256 fingerprints in NA73128_Workstream_Manifest_10-Jun-2026.csv
A15: 11 | B15: Document | C15: n/a (unplaced) | D15: BCC King George Square parking receipt 89991, 4-Jun-2025, $42.15 net + $4.21 GST (card ...1627 Anita Moore) | E15: Identified-unplaced; FY25 document, no in-scope FY26 match; likely FY25 73531; archived _Sources_10-Jun-2026/ pending instruction
A16: 12 | B16: Document | C16: n/a (unplaced) | D16: Six IPWEA documents (R58890, 40310, 40309, two QNT Stripe receipts x3 copies) | E16: Identified-unplaced; attendees not in Parks; archived _Sources_10-Jun-2026/ pending instruction
... A67: 63 | B67: Register decision | C67: Sequence | D67: Priority sequence: finish in-flight then materiality. P2 accounts 73126, 73212, 73123, 73990 | E67: Open
