Workbook

Sheet Summary
A1: PARKS BRANCH 4090000 — CONSOLIDATED CODING-REVIEW JOURNAL | Reconciliation & Drill-Down
A2: Spero Karkalemis, Assistant Financial Analyst • Prepared 3-Jun-2026 • All amounts GST-exclusive • TechOne PK ledger
A4: Total lines | C4: Batch balance | E4: Review streams | G4: Gross debits
A5: =COUNTA('Consolidated Journal'!$A$5:$A$150) -> 146 | C5: ='Consolidated Journal'!G151 -> 0 | E5: 5 | G5: =SUMIF('Consolidated Journal'!$G$5:$G$150,">0") -> 28802.17
A7: Gross credits | C7: 73563 moved out | E7: 72111 moved out | G7: Outstanding flags
A8: =SUMIF('Consolidated Journal'!$G$5:$G$150,"<0") -> -28802.17 | C8: =-SUMIF('Consolidated Journal'!$F$5:$F$150,"73563",'Consolidated Journal'!$G$5:$G$150) -> 4908.42 | E8: =-SUMIF('Consolidated Journal'!$F$5:$F$150,"72111",'Consolidated Journal'!$G$5:$G$150) -> 21790.44 | G8: 4
A12: DRILL 1 — By review stream (each stream must net to $0.00)
A13: Review stream | B13: Lines | C13: Gross Dr | D13: Gross Cr | E13: Net (must=0)
A14: WINC 73563 P1-P10 | B14: =COUNTIF('Consolidated Journal'!$A$5:$A$150,A14) -> 26 | C14: =SUMIFS('Consolidated Journal'!$G$5:$G$150,'Consolidated Journal'!$A$5:$A$150,A14,'Consolidated Journal'!$G$5:$G$150,">0") -> 3852.64 | D14: =SUMIFS('Consolidated Journal'!$G$5:$G$150,'Consolidated Journal'!$A$5:$A$150,A14,'Consolidated Journal'!$G$5:$G$150,"<0") -> -3852.64 | E14: =SUMIF('Consolidated Journal'!$A$5:$A$150,A14,'Consolidated Journal'!$G$5:$G$150) -> 0
A15: WINC 73563 Apr-2026 | B15: =COUNTIF('Consolidated Journal'!$A$5:$A$150,A15) -> 12 | C15: =SUMIFS('Consolidated Journal'!$G$5:$G$150,'Consolidated Journal'!$A$5:$A$150,A15,'Consolidated Journal'!$G$5:$G$150,">0") -> 1187.61 | D15: =SUMIFS('Consolidated Journal'!$G$5:$G$150,'Consolidated Journal'!$A$5:$A$150,A15,'Consolidated Journal'!$G$5:$G$150,"<0") -> -1187.61 | E15: =SUMIF('Consolidated Journal'!$A$5:$A$150,A15,'Consolidated Journal'!$G$5:$G$150) -> 0
A16: 72111 Minor Equip Audit | B16: =COUNTIF('Consolidated Journal'!$A$5:$A$150,A16) -> 91 | C16: =SUMIFS('Consolidated Journal'!$G$5:$G$150,'Consolidated Journal'!$A$5:$A$150,A16,'Consolidated Journal'!$G$5:$G$150,">0") -> 22028.13 | D16: =SUMIFS('Consolidated Journal'!$G$5:$G$150,'Consolidated Journal'!$A$5:$A$150,A16,'Consolidated Journal'!$G$5:$G$150,"<0") -> -22028.13 | E16: =SUMIF('Consolidated Journal'!$A$5:$A$150,A16,'Consolidated Journal'!$G$5:$G$150) -> 0
A17: PCard Batch (Officeworks/Flair/Oasis) | B17: =COUNTIF('Consolidated Journal'!$A$5:$A$150,A17) -> 11 | C17: =SUMIFS('Consolidated Journal'!$G$5:$G$150,'Consolidated Journal'!$A$5:$A$150,A17,'Consolidated Journal'!$G$5:$G$150,">0") -> 674.03 | D17: =SUMIFS('Consolidated Journal'!$G$5:$G$150,'Consolidated Journal'!$A$5:$A$150,A17,'Consolidated Journal'!$G$5:$G$150,"<0") -> -674.03 | E17: =SUMIF('Consolidated Journal'!$A$5:$A$150,A17,'Consolidated Journal'!$G$5:$G$150) -> 0
A18: Reali Uniforms PK split | B18: =COUNTIF('Consolidated Journal'!$A$5:$A$150,A18) -> 6 | C18: =SUMIFS('Consolidated Journal'!$G$5:$G$150,'Consolidated Journal'!$A$5:$A$150,A18,'Consolidated Journal'!$G$5:$G$150,">0") -> 1059.76 | D18: =SUMIFS('Consolidated Journal'!$G$5:$G$150,'Consolidated Journal'!$A$5:$A$150,A18,'Consolidated Journal'!$G$5:$G$150,"<0") -> -1059.76 | E18: =SUMIF('Consolidated Journal'!$A$5:$A$150,A18,'Consolidated Journal'!$G$5:$G$150) -> 0
A19: TOTAL | B19: =SUM(B14:B18) -> 146 | C19: =SUM(C14:C18) -> 28802.17 | D19: =SUM(D14:D18) -> -28802.17 | E19: =SUM(E14:E18) -> 0
A21: DRILL 2 — By natural account (net signed movement: negative = moved OUT, positive = moved IN)
A22: NA | B22: Account name | C22: Net movement
A23: 72111 | B23: Minor Equipment & Supplies | C23: =SUMIF('Consolidated Journal'!$F$5:$F$150,A23,'Consolidated Journal'!$G$5:$G$150) -> -21790.44
A24: 72112 | B24: Chemical, fertiliser & paints | C24: =SUMIF('Consolidated Journal'!$F$5:$F$150,A24,'Consolidated Journal'!$G$5:$G$150) -> 1628.93
A25: 72113 | B25: Safety Equipment & Medical | C25: =SUMIF('Consolidated Journal'!$F$5:$F$150,A25,'Consolidated Journal'!$G$5:$G$150) -> 5133.27
A26: 72114 | B26: Uniforms | C26: =SUMIF('Consolidated Journal'!$F$5:$F$150,A26,'Consolidated Journal'!$G$5:$G$150) -> 0
A27: 72222 | B27: Signs | C27: =SUMIF('Consolidated Journal'!$F$5:$F$150,A27,'Consolidated Journal'!$G$5:$G$150) -> 927
A28: 72231 | B28: Landscape Supplies | C28: =SUMIF('Consolidated Journal'!$F$5:$F$150,A28,'Consolidated Journal'!$G$5:$G$150) -> 1409.84
A29: 72248 | B29: Crusher Dust | C29: =SUMIF('Consolidated Journal'!$F$5:$F$150,A29,'Consolidated Journal'!$G$5:$G$150) -> 1387.55
A30: 72249 | B30: Topsoil | C30: =SUMIF('Consolidated Journal'!$F$5:$F$150,A30,'Consolidated Journal'!$G$5:$G$150) -> 2942.24
A31: 72311 | B31: Other Plant & Equipment | C31: =SUMIF('Consolidated Journal'!$F$5:$F$150,A31,'Consolidated Journal'!$G$5:$G$150) -> 4286.05
A32: 72313 | B32: Furniture & Fittings | C32: =SUMIF('Consolidated Journal'!$F$5:$F$150,A32,'Consolidated Journal'!$G$5:$G$150) -> 452.7
A33: 72315 | B33: Parks Assets | C33: =SUMIF('Consolidated Journal'!$F$5:$F$150,A33,'Consolidated Journal'!$G$5:$G$150) -> 1250
A34: 73211 | B34: Contractors | C34: =SUMIF('Consolidated Journal'!$F$5:$F$150,A34,'Consolidated Journal'!$G$5:$G$150) -> 1707.25
... A39: 73564 | B39: IT Equipment & Applications | C39: =SUMIF('Consolidated Journal'!$F$5:$F$150,A39,'Consolidated Journal'!$G$5:$G$150) -> 2372.84
B40: TOTAL (must=0) | C40: =SUM(C23:C39) -> 0
A42: DRILL 3 — By PK (net signed movement: 0 = recode stayed within PK; non-zero = cross-PK relocation)
A43: PK | B43: Lines | C43: Net movement
A44: PK000001 | B44: =COUNTIF('Consolidated Journal'!$C$5:$C$150,A44) -> 36 | C44: =SUMIF('Consolidated Journal'!$C$5:$C$150,A44,'Consolidated Journal'!$G$5:$G$150) -> -1059.76
A45: PK000003 | B45: =COUNTIF('Consolidated Journal'!$C$5:$C$150,A45) -> 5 | C45: =SUMIF('Consolidated Journal'!$C$5:$C$150,A45,'Consolidated Journal'!$G$5:$G$150) -> 45.29
A46: PK000012 | B46: =COUNTIF('Consolidated Journal'!$C$5:$C$150,A46) -> 33 | C46: =SUMIF('Consolidated Journal'!$C$5:$C$150,A46,'Consolidated Journal'!$G$5:$G$150) -> 102.78
A47: PK000022 | B47: =COUNTIF('Consolidated Journal'!$C$5:$C$150,A47) -> 2 | C47: =SUMIF('Consolidated Journal'!$C$5:$C$150,A47,'Consolidated Journal'!$G$5:$G$150) -> 0
A48: PK000032 | B48: =COUNTIF('Consolidated Journal'!$C$5:$C$150,A48) -> 2 | C48: =SUMIF('Consolidated Journal'!$C$5:$C$150,A48,'Consolidated Journal'!$G$5:$G$150) -> 0
A49: PK000055 | B49: =COUNTIF('Consolidated Journal'!$C$5:$C$150,A49) -> 2 | C49: =SUMIF('Consolidated Journal'!$C$5:$C$150,A49,'Consolidated Journal'!$G$5:$G$150) -> 0
A50: PK000068 | B50: =COUNTIF('Consolidated Journal'!$C$5:$C$150,A50) -> 18 | C50: =SUMIF('Consolidated Journal'!$C$5:$C$150,A50,'Consolidated Journal'!$G$5:$G$150) -> 0
A51: PK000075 | B51: =COUNTIF('Consolidated Journal'!$C$5:$C$150,A51) -> 2 | C51: =SUMIF('Consolidated Journal'!$C$5:$C$150,A51,'Consolidated Journal'!$G$5:$G$150) -> 0
...

Sheet Consolidated Journal
A1: CONSOLIDATED RECODE JOURNAL — TechOne GENJNL (PK Ledger) | Parks Branch 4090000 | Prepared 3-Jun-2026
A2: 40-char per narrative field. Dr positive, Cr negative. Batch must net to $0.00. Streams individually balanced.
A4: Stream | B4: LDG | C4: Account (PK) | D4: Fund Account | E4: Resource Group | F4: Resource (NA) | G4: Amount | H4: Narrative 1 | I4: Narrative 2 | J4: Narrative 3
A5: WINC 73563 P1-P10 | B5: PK | C5: PK000001 | D5: PK000001 | E5: JOURNAL | F5: 73563 | G5: -498.61 | H5: Recode WINC non-stat frm 73563 | I5: Cleaning batt kitchen tools | J5: To 72111 Minor Equip & Supplies
A6: WINC 73563 P1-P10 | B6: PK | C6: PK000001 | D6: PK000001 | E6: JOURNAL | F6: 72111 | G6: 498.61 | H6: Recode WINC non-stat frm 73563 | I6: Cleaning batt kitchen tools | J6: To 72111 Minor Equip & Supplies
A7: WINC 73563 P1-P10 | B7: PK | C7: PK000001 | D7: PK000001 | E7: JOURNAL | F7: 73563 | G7: -36.62 | H7: Recode WINC non-stat frm 73563 | I7: Cleaning batt kitchen tools | J7: To 72111 Minor Equip & Supplies
A8: WINC 73563 P1-P10 | B8: PK | C8: PK000001 | D8: PK000001 | E8: JOURNAL | F8: 72111 | G8: 36.62 | H8: Recode WINC non-stat frm 73563 | I8: Cleaning batt kitchen tools | J8: To 72111 Minor Equip & Supplies
A9: WINC 73563 P1-P10 | B9: PK | C9: PK000001 | D9: PK000001 | E9: JOURNAL | F9: 73563 | G9: -58.58 | H9: Recode WINC non-stat frm 73563 | I9: Cleaning batt kitchen tools | J9: To 72111 Minor Equip & Supplies
A10: WINC 73563 P1-P10 | B10: PK | C10: PK000001 | D10: PK000001 | E10: JOURNAL | F10: 72111 | G10: 58.58 | H10: Recode WINC non-stat frm 73563 | I10: Cleaning batt kitchen tools | J10: To 72111 Minor Equip & Supplies
A11: WINC 73563 P1-P10 | B11: PK | C11: PK000001 | D11: PK000001 | E11: JOURNAL | F11: 73563 | G11: -15.56 | H11: Recode WINC fly spray frm 73563 | I11: Mortein insect spray | J11: To 72112 Chemical & Pesticide
A12: WINC 73563 P1-P10 | B12: PK | C12: PK000001 | D12: PK000001 | E12: JOURNAL | F12: 72112 | G12: 15.56 | H12: Recode WINC fly spray frm 73563 | I12: Mortein insect spray | J12: To 72112 Chemical & Pesticide
A13: WINC 73563 P1-P10 | B13: PK | C13: PK000001 | D13: PK000001 | E13: JOURNAL | F13: 73563 | G13: 23.57 | H13: Recode WINC PPE frm 73563 | I13: First aid vest, nitrile gloves | J13: To 72113 Safety Equipment
A14: WINC 73563 P1-P10 | B14: PK | C14: PK000001 | D14: PK000001 | E14: JOURNAL | F14: 72113 | G14: -23.57 | H14: Recode WINC PPE frm 73563 | I14: First aid vest, nitrile gloves | J14: To 72113 Safety Equipment
A15: WINC 73563 P1-P10 | B15: PK | C15: PK000001 | D15: PK000001 | E15: JOURNAL | F15: 73563 | G15: -1305.86 | H15: Recode WINC tearoom frm 73563 | I15: Coffee tea sugar ice (Reason B) | J15: To 73512 Hospitality Non-FBT
A16: WINC 73563 P1-P10 | B16: PK | C16: PK000001 | D16: PK000001 | E16: JOURNAL | F16: 73512 | G16: 1305.86 | H16: Recode WINC tearoom frm 73563 | I16: Coffee tea sugar ice (Reason B) | J16: To 73512 Hospitality Non-FBT
... A133: 72111 Minor Equip Audit | B133: PK | C133: PK000012 | D133: PK000012 | E133: JOURNAL | F133: 72111 | G133: -334.16 | H133: J35k recode: STKISS STAR PICKE WD26 | I133: Ref 097868 Svc 20181 (PK000012) | J133: From 72111
A134: PCard Batch (Officeworks/Flair/Oasis) | B134: PK | C134: PK000001 | D134: PK000001 | E134: JOURNAL | F134: 72111 | G134: -77.27 | H134: 22-Jan-2026 | I134: SP FLAIR FLORAL
A135: PCard Batch (Officeworks/Flair/Oasis) | B135: PK | C135: PK000001 | D135: PK000001 | E135: JOURNAL | F135: 73513 | G135: 77.27 | H135: 22-Jan-2026 | I135: SP FLAIR FLORAL
A136: PCard Batch (Officeworks/Flair/Oasis) | B136: PK | C136: PK000001 | D136: PK000001 | E136: JOURNAL | F136: 72111 | G136: -473.64 | H136: 13-Jan-2026 | I136: OFFICEWORKS
A137: PCard Batch (Officeworks/Flair/Oasis) | B137: PK | C137: PK000001 | D137: PK000001 | E137: JOURNAL | F137: 73563 | G137: 43.64 | H137: 3× 2026 Collins A5 Diary | I137: OFFICEWORKS
A138: PCard Batch (Officeworks/Flair/Oasis) | B138: PK | C138: PK000001 | D138: PK000001 | E138: JOURNAL | F138: 72313 | G138: 398.18 | H138: 20× Otto Acrylic Desk Riser Large + 2× N | I138: OFFICEWORKS
A139: PCard Batch (Officeworks/Flair/Oasis) | B139: PK | C139: PK000001 | D139: PK000001 | E139: JOURNAL | F139: 73564 | G139: 31.82 | H139: 1× USB-C / SD Card Reader Adapter | I139: OFFICEWORKS
A140: PCard Batch (Officeworks/Flair/Oasis) | B140: PK | C140: PK000001 | D140: PK000001 | E140: JOURNAL | F140: 72313 | G140: 54.52 | H140: 3× Otto Acrylic Desk Riser Large | I140: OFFICEWORKS
A141: PCard Batch (Officeworks/Flair/Oasis) | B141: PK | C141: PK000001 | D141: PK000001 | E141: JOURNAL | F141: 73563 | G141: 41.05 | H141: 1× Posca PC5M Paint Marker pack of 8
A142: PCard Batch (Officeworks/Flair/Oasis) | B142: PK | C142: PK000001 | D142: PK000001 | E142: JOURNAL | F142: 72111 | G142: -95.57 | H142: TE004824
A143: PCard Batch (Officeworks/Flair/Oasis) | B143: PK | C143: PK000001 | D143: PK000001 | E143: JOURNAL | F143: 72248 | G143: 27.55 | H143: TE004478
A144: PCard Batch (Officeworks/Flair/Oasis) | B144: PK | C144: PK000001 | D144: PK000001 | E144: JOURNAL | F144: 72111 | G144: -27.55 | H144: TE004478
A145: Reali Uniforms PK split | B145: PK | C145: PK000012 | D145: PK000012 | E145: JOURNAL | F145: 72114 | G145: 102.78 | H145: Reali uniform recode fr 20151 | I145: PO702344 SI consol Mar-2026 | J145: 72114 net-mvmt (confirm w Fin)
A146: Reali Uniforms PK split | B146: PK | C146: PK000433 | D146: PK000433 | E146: JOURNAL | F146: 72114 | G146: 229.34 | H146: Reali uniform recode fr 20151 | I146: PO702344 SI consol Mar-2026 | J146: 72114 net-mvmt (confirm w Fin)
A147: Reali Uniforms PK split | B147: PK | C147: PK000435 | D147: PK000435 | E147: JOURNAL | F147: 72114 | G147: 589.63 | H147: Reali uniform recode fr 20151 | I147: PO702344 SI consol Mar-2026 | J147: 72114 net-mvmt (confirm w Fin)
A148: Reali Uniforms PK split | B148: PK | C148: PK000003 | D148: PK000003 | E148: JOURNAL | F148: 72114 | G148: 45.29 | H148: Reali uniform recode fr 20151 | I148: PO702344 SI consol Mar-2026 | J148: 72114 net-mvmt (confirm w Fin)
A149: Reali Uniforms PK split | B149: PK | C149: PK000402 | D149: PK000402 | E149: JOURNAL | F149: 72114 | G149: 92.72 | H149: Reali uniform recode fr 20151 | I149: PO702344 SI consol Mar-2026 | J149: 72114 net-mvmt (confirm w Fin)
A150: Reali Uniforms PK split | B150: PK | C150: PK000001 | D150: PK000001 | E150: JOURNAL | F150: 72114 | G150: -1059.76 | H150: Reali uniform recode fr 20151 | I150: PO702344 SI consol Mar-2026 | J150: 72114 net-mvmt incl 1c round
F151: BATCH NET | G151: =SUM(G5:G150) -> 0

Sheet April WINC Detail
A1: WINC INVOICE 9901782965 — APRIL 2026 | Line-Item Classification | Parks accts 10179376 (PK000001) + 10428958 (PK000086)
A2: 39 Parks lines, all currently coded 73563. Amounts GST-exclusive. GREEN = correctly in 73563; AMBER = miscoded, recode in consolidated journal.
A4: PK | B4: Item code | C4: Description | D4: Qty | E4: Amount | F4: Current | G4: Suggested | H4: Treatment | I4: Status
A5: PK000001 | B5: 85204000 | C5: Nescafe Classic Decaf Inst Coff 375g Tin | D5: 2 | E5: 62.26 | F5: 73563 | G5: 73512 | H5: Hospitality refreshments (Reason B) | I5: MISCODE
A6: PK000001 | B6: 86514699 | C6: Nestle Milo Tin 1.9kg | D6: 2 | E6: 75.76 | F6: 73563 | G6: 73512 | H6: Hospitality refreshments (Reason B) | I6: MISCODE
A7: PK000001 | B7: 86547541 | C7: Lipton Tbg Pk100 | D7: 2 | E7: 16.34 | F7: 73563 | G7: 73512 | H7: Hospitality refreshments (Reason B) | I7: MISCODE
A8: PK000001 | B8: 25184215 | C8: Moccona Med Roast Instant Coff 1kg Tin | D8: 2 | E8: 134.08 | F8: 73563 | G8: 73512 | H8: Hospitality refreshments (Reason B) | I8: MISCODE
A9: PK000001 | B9: 86551332 | C9: Any Yr Dry A5 1 Day/Pg | D9: 5 | E9: 199.95 | F9: 73563 | G9: 73563 | H9: Stationery / printing | I9: OK
A10: PK000001 | B10: 25194636 | C10: Energizer Lithium AA Batts 10pk | D10: 1 | E10: 49.99 | F10: 73563 | G10: 72111 | H10: Minor equipment / batteries | I10: MISCODE
A11: PK000001 | B11: 87215078 | C11: Winc Rtrct Blpnt Pn Blk 1.0mm Pk 12 | D11: 1 | E11: 3.31 | F11: 73563 | G11: 73563 | H11: Stationery / printing | I11: OK
A12: PK000001 | B12: 87215079 | C12: Winc Rtrct Blpnt Pn Blu 1.0mm Pk 12 | D12: 1 | E12: 3.31 | F12: 73563 | G12: 73563 | H12: Stationery / printing | I12: OK
A13: PK000001 | B13: 25204912 | C13: Voyager 4320 Wireless Uc Stereo USB-A | D13: 1 | E13: 185.51 | F13: 73563 | G13: 73564 | H13: IT equipment / accessories | I13: MISCODE
A14: PK000001 | B14: 86518485 | C14: Staedtler 351 Wbrd Mrkr St 6 | D14: 1 | E14: 11.65 | F14: 73563 | G14: 73563 | H14: Stationery / printing | I14: OK
A15: PK000001 | B15: 86602621 | C15: Spirax 571 Notebook A5 300Pg | D15: 1 | E15: 3.97 | F15: 73563 | G15: 73563 | H15: Stationery / printing | I15: OK
A16: PK000001 | B16: 18885357 | C16: Winc Spiral Ntebk No. 337 A5 Prf 200 Pgs | D16: 1 | E16: 3.21 | F16: 73563 | G16: 73563 | H16: Stationery / printing | I16: OK
... A43: PK000086 | B43: 10006619 | C43: Winc AAA Prem Alkal Batt Bx 24 | D43: 1 | E43: 6.64 | F43: 73563 | G43: 72111 | H43: Minor equipment / batteries | I43: MISCODE
D44: TOTAL | E44: =SUM(E5:E43) -> 1676.26
D45: Miscoded (recoded out) | E45: =SUMIF(I5:I43,"MISCODE",E5:E43) -> 1187.61
D46: Correctly in 73563 | E46: =SUMIF(I5:I43,"OK",E5:E43) -> 488.65

Sheet Verification & Findings
A1: VERIFICATION & FINDINGS | Consolidated Coding-Review Journal | Parks Branch 4090000
A2: RED = blocker, resolve before upload • AMBER = confirm before upload • GREEN = verified clean • Prepared 3-Jun-2026
A4: 1 — BLOCKER (resolve before upload)
A5: Flag | B5: Stream / area | C5: Item / ref | D5: Finding | E5: $ impact | F5: Action required
A6: RED | B6: 72111 Audit vs PCard Batch | C6: Doc46 J12 / TE005091 vs Officeworks inv 626529478 | D6: J12 recodes "20 desk risers" 72111 to 72313 ($363.64). The same 20 Otto risers are already split in the PCard Batch (Doc45) recode of Officeworks inv 626529478 ($398.18 = 20 Otto + 2 mesh + adapter). Booking both double-counts the riser relocation. | E6: 363.64 | F6: CONFIRM TE005091 is the riser line of inv 626529478. If yes, J12 stays removed from the batch (already excluded here). If a separate purchase, re-add J12 (2 lines).
A8: 2 — CONFIRM BEFORE UPLOAD
A9: Flag | B9: Stream / area | C9: Item / ref | D9: Finding | E9: $ impact | F9: Action required
A10: AMBER | B10: PCard Batch (Flair Floral) | C10: Flair Floral $77.27 / PK000001 | D10: Reversal in Doc45 lifts from 72111, but the P-Card cover slip wrote the cost to 71111 (Full Time Staff). Reversal source must equal the live GL line. | E10: 77.27 | F10: Confirm live GL coding: if it sits in 71111, change the reversal source from 72111 to 71111 before upload.
A11: AMBER | B11: Reali Uniforms | C11: PO702344 / inv PKLCC2026-0331 | D11: Reali stream uses net-movement format (DR five PKs, CR PK000001); the four other streams use full-reversal. NA 72114 correct throughout, PK split is the only correction. | E11: 1059.76 | F11: Confirm Finance accepts net-movement for this batch, or convert to full-reversal per their preference.
A12: AMBER | B12: Travel — Gold Coast parking | C12: TE004218 / 73541 to 73531 | D12: City of Gold Coast parking $6.05, Craig Logan P-Card 16-Jun-2025, miscoded to 73541 Conferences. SEQ parking belongs in 73531 Local Travel. Not in this batch (need home PK). | E12: 6.05 | F12: Provide Craig Logan home PK to build the 73541 to 73531 recode line.
A13: AMBER | B13: Travel — Cabcharge | C13: Jan-2026 statement $787.74 | D13: Mixed local SEQ legs (73531) and interstate Melbourne/Geelong legs (73533). Needs per-traveller split. Not in this batch (need current GL coding + per-traveller PK + hotel-to-hotel destination). | E13: 787.74 | F13: Provide current GL coding, per-traveller PK, and trip destinations to split 73531 vs 73533.
A15: 3 — CARRY-FORWARD OPEN ITEM
A16: Flag | B16: Stream / area | C16: Item / ref | D16: Finding | E16: $ impact | F16: Action required
A17: AMBER | B17: WINC 73563 | C17: inv 9901763737 / Feb-2026 | D17: Hits GL in P9. PDF still absent from the pack, so no line-item classification possible. Flagged in prior findings, remains open. | E17: 1240.45 | F17: Obtain the PDF for inv 9901763737 to complete the WINC 73563 audit trail.
A19: 4 — VERIFIED CLEAN
A20: Flag | B20: Stream / area | C20: Item / ref | D20: Finding | E20: $ impact | F20: Action required
A21: GREEN | B21: Batch integrity | C21: All 5 streams | D21: Consolidated batch nets to $0.00. Each stream balances individually: WINC P1-P10, WINC Apr, 72111 Audit (minus J12), PCard Batch, Reali. | E21: Nil | F21: None.
A22: GREEN | B22: Source docs balance | C22: Doc45 / Doc46 | D22: TechOne exports Doc File 1227681 (PCard) and 1226060 (72111 audit) both balance to $0.00 as extracted. | E22: Nil | F22: None.
A23: GREEN | B23: Destination accounts | C23: All NAs | D23: Every destination natural account exists in the Chart of Accounts and is UNRESTRICTED (72111/72112/72113/72114/72222/72231/72248/72249/72311/72313/72315/73211/73220/73512/73513/73563/73564). | E23: Nil | F23: None.
A24: GREEN | B24: PK / service map | C24: All PKs | D24: All PKs valid; narration service codes reconcile to the service-section map. Sub-PKs PK000445/PK000083/PK000493 not in the 101-row parent CSV but their services (20451/20392) are valid. | E24: Nil | F24: None.
A25: GREEN | B25: April classification | C25: inv 9901782965 | D25: 39 Parks lines reconciled: $1,676.26 total = $1,187.61 miscoded + $488.65 correctly in 73563. Aggregate recode matches line detail exactly. | E25: Nil | F25: None.
A26: GREEN | B26: Travel taxonomy | C26: 73531-73541 | D26: Confirmed: 73531 Local SEQ, 73532 Intrastate QLD, 73533 Interstate, 73534 Overseas, 73535 Tollway, 73541 Conferences (registration only). Gold Coast = SEQ. | E26: Nil | F26: None.
